Workbook

Sheet 2025 DWR Respondents
A1: Submission Datetime | B1: Email Address | C1: Month | D1: Week | E1: Worker's Full Name | F1: Branch | G1: How many days did you join church WhatsApp Prayer? | H1: How has participating in WhatsApp prayer impacted your spiritual life? | I1: Did you attend Bible Study? | J1: If YES above, What specific insight did you gain from the Bible study this week? | K1: Did you attend Gethsemane/Vigil/House Fellowship? | L1: If YES above, What was the most impactful moment or teaching from this gathering? | M1: Kindly Upload the Written Notes of Your Weekly Bible Study | N1: Have you given towards Church Project Contribution? | O1: If NO, what challenges are preventing you from making your financial contributions? | P1: Did you listen to (or watch) THE WORD OF HIS GRACE on Diamond 88.5FM? | Q1: If YES, how has listening to 'The Word of His Grace' inspired you to live a more Christ-like life? | R1: Did you go for Evangelism? | S1: If YES, What is the total number of People Saved? | T1: Kindly upload a Well Written Evangelism Record (Follow the template given above) | U1: Additional Comment(s) | V1: Did you visit your Disciple(s)? | W1: If NO, why? | X1: Kindly upload a Well Written Evangelism Record (Follow the template given above)2 | Y1: Additional Comment(s)3
A2: 45687.737 | B2: oniyiderebecca17@gmail.com | C2: January | D2: Week 2 | E2: Oniyide Rebecca | F2: University of Ilesa, Osun State | G2: Mostly in the morning | H2: It has help to maintain a consistent prayer life | I2: Yes | J2: https://drive.google.com/open?id=19ODOlAd89TQgO4kyPS6-Z-xhicmTAXAS | K2: Yes | L2: https://drive.google.com/open?id=14fBPwMyKlIcut6umZEBAiCgwY59BTDuS | M2: https://drive.google.com/open?id=12LzUt1oKBXX_eZrsh8BITzbzqaZrVM8g | N2: No | O2: Have spent a lot for the festive season. | P2: Yes | Q2: Am blessed and edified through the word | R2: Yes | S2: 2 | T2: https://drive.google.com/open?id=1QzPNUc9cEHVsNv6o53pM4cxFmtgebsNK | V2: Yes | W2: I visited her | X2: https://drive.google.com/open?id=1M4g8XQRlPgj1j0i-vKnz3rcSl-Y-QtG2
A3: 45689.872 | B3: Adetumiadefokun@gmail.com | C3: January | D3: Week 5 | E3: Adefokun Adetumi Ebenezer | F3: Ipetu-Ijesha, Osun State | G3: 6days | H3: To pray better | I3: Yes | J3: https://drive.google.com/open?id=11s2Yzi6MFSapxj50Oyy2TgCCCDhLBTzt | K3: Yes | L3: https://drive.google.com/open?id=1UflfGiaE0a6EsDFSIqIU58FxCOruAEqYQNXNXWBaEIY | M3: https://drive.google.com/open?id=1FvzrE4CjqdpK6WAW2UNRzOjqbGgnAeOx | N3: Yes | P3: Yes | Q3: To know more about grace of God | R3: Yes | S3: 2 | T3: https://drive.google.com/open?id=1Z8ma06GtF4RX_fidb-R-o_IFCo74IcK- | V3: Yes | W3: G | X3: https://drive.google.com/open?id=1Z-zqSWn6FVLIk0tfxLsTL9JtQsKtNznx
A4: 45689.885 | B4: akerewusioluwadamilare@gmail.com | C4: January | D4: Week 5 | E4: Akerewusi Oluwadamilare | F4: University of Ilesa, Osun State | G4: Every day | H4: It has been helpful. | I4: Yes | J4: https://drive.google.com/open?id=1GEhuEzxZtlKE3XljleCm2a21hDzC9lBZ, https://drive.google.com/open?id=1UyYq_6K8jc_Cv3dMg94rEX2wUulfQp_Z | K4: Yes | L4: https://drive.google.com/open?id=1ZIo_9CSnJzaff9-YXMtIn2YIRz4jW-0h | M4: https://drive.google.com/open?id=1ne2Ch_45MkmyE0p2J4iLPGeXyI9v3Ptn | N4: Yes | P4: Yes | Q4: It has been helpful as reminder to the basics of Christianity. | R4: Yes | S4: I don't understand this question. It is not clear because it's not detailed enough or not specific. | T4: https://drive.google.com/open?id=1CEJKw6yUIfqLCJBmDv56-Tm7qQ_h6dFO | V4: Yes | W4: Nil | X4: https://drive.google.com/open?id=11MtNOIWgYhduUjNewUpMT_gK5YDZyTIF | Y4: Kindly work on the asterisk question very well.
A5: 45689.922 | B5: akinleyeayomidedeborah@gmail.com | C5: February | D5: Week 1 | E5: Akinleye Ayomide Deborah | F5: Health Tech Bolorunduro, Ilesa, Osun State | G5: 5 | H5: Fervent more | I5: Yes | J5: https://drive.google.com/open?id=185OMPGpyV14_3Ywf9ikUou7KGMtY-GSp | K5: Yes | L5: https://drive.google.com/open?id=1CPohZLzy0xQHwGwfnESGOwq2itUttN56 | M5: https://drive.google.com/open?id=1bE0Z4KsReUSR9c07jcDd9PMZDimfMHUH | N5: No | P5: Yes | Q5: Know more about Christ | R5: Yes | S5: 2 | T5: https://drive.google.com/open?id=1zAnsjfeTZX-VOHRHNtJ_S_-SJfpMll_V | V5: No | W5: Not around | X5: https://drive.google.com/open?id=1r-oflYql2aDq1jNOVeGSMK75y23adjbI
A6: 45689.933 | B6: lorleybee@gmail.com | C6: January | D6: Week 5 | E6: Durodola Ololade | F6: Esa-Oke, Osun State | G6: 5days | H6: To pray for other things | I6: Yes | J6: https://drive.google.com/open?id=1fR-yR93yhIOMmdx8U029wEIOQnUEh_XlyGlU-Y8rnJw | K6: Yes | L6: https://drive.google.com/open?id=1S-IhWZQ-1eihxDpjxA5PIf2LQzPvw6BOGhFhgX-W_Eg | M6: https://drive.google.com/open?id=1IftDr8MhE7fUDg7G6cICTQIu47scNeJdxmkkB77DnAU | N6: Yes | P6: Yes | Q6: Excellent | R6: Yes | S6: Three | T6: https://drive.google.com/open?id=1rkh0G1EHc77ffH0Xap53q7kQL4ZLZRsKc1ABcaKRzrw | U6: Nothing yet | V6: Yes | W6: None | X6: https://drive.google.com/open?id=1JHm4IGcPhhG1LxdGDcFNuwGbs9jRw3z2gl9aCbD155o | Y6: None
A7: 45690.087 | B7: ogundareolamideemmanuel@gmail.com | C7: February | D7: Week 1 | E7: Ogundare Olamide Emmanuel | F7: Headquarters, Egbe-Idi, Ilesa, Osun State | G7: 4 | H7: It has Greatly impacted me. | I7: Yes | J7: https://drive.google.com/open?id=1fSL9D6FHxSya6yL_SEPT53g7yIterv3T | K7: Yes | L7: https://drive.google.com/open?id=1nVBMs0zdlZ9h4u5GpJY_ijErZtBhxw63 | M7: https://drive.google.com/open?id=1chXvHdx4rIQT5o9cpw5gz6WpcpQLsq2O | N7: Yes | P7: Yes | Q7: Greatly | R7: Yes | S7: 0 | T7: https://drive.google.com/open?id=17nmzid0PBEFr0t4wka16u8sTjoAquQX6 | V7: Yes | W7: Nay | X7: https://drive.google.com/open?id=1tjZi2HgMhAFu66B1kYlw_spkH3scVTe5
A8: 45690.109 | B8: ogundareolamideemmanuel@gmail.com | C8: January | D8: Week 3 | E8: Ogundare Olamide Emmanuel | F8: Esa-Oke, Osun State | G8: 0 | H8: Greatly | I8: Yes | J8: https://drive.google.com/open?id=1d9D6wVtvdjybQ3YqafaHb-_wy7xeogx7 | K8: Yes | L8: https://drive.google.com/open?id=13XtZlSXkpJT4L05EU89nctUqUCyRntYO | M8: https://drive.google.com/open?id=1THskM0tFk7LyOdj1kB8lR4-J8JrTq8dq | N8: Yes | P8: Yes | Q8: Greatly | R8: Yes | T8: https://drive.google.com/open?id=1s87JJQFRkOr3nUG89SwwcGq23nD_NgNb | V8: Yes | X8: https://drive.google.com/open?id=1a8bFwB7AVhHrk_9ewg25V36rCvZQyXoh
A9: 45690.585 | B9: abattayo@gmail.com | C9: February | D9: Week 1 | E9: Abayomi Temitayo Ezekiel | F9: Health Tech Bolorunduro, Ilesa, Osun State | G9: 4 | H9: Positively | I9: Yes | J9: https://drive.google.com/open?id=1gSFrS7XCuxeAk4Zh62ehLJe302pWSQC3 | K9: Yes | L9: https://drive.google.com/open?id=1o99cb9VzbBhRj45lC_i_T0SYTt8au4Tm | M9: https://drive.google.com/open?id=1YBwSEYcHdI4U8fbjQad0gasI1Qj1IvUk | N9: No | O9: Incoming | P9: Yes | Q9: Great | R9: No | S9: Gfc | T9: https://drive.google.com/open?id=1KHDcKKiQdCqHvUAjxAch0xWIWX91sFi6 | U9: Ggff | V9: No | W9: Fhh | X9: https://drive.google.com/open?id=17JGVwh1hHc-wc84P5tzckg-K1SXhyaiD | Y9: Ggsh
A10: 45698.411 | B10: oyewumimary99@gmail.com | C10: February | D10: Week 1 | E10: Oyewumi Mary.A | F10: University of Ilesa, Osun State | G10: 4 | H10: It has helped me in having personal prayer life | I10: No | J10: I didn't attend Bible study | K10: Yes | L10: I was not in Bible study | M10: https://drive.google.com/open?id=1xzUiCwwIkGaYfwcO9h0vBm6AN_tVKCCc | N10: No | O10: I don't have much yet | P10: Yes | Q10: Righteousness We have two kinds of righteousness Self righteousness Deut6 verse 25 and God kind of righteousness Rom3 verse 19 Nobody can be made righteous by keeping the law because it's the law that made sin known God kind of righteousness it's faith in death burial and resurrection of Christ | R10: No | S10: None | T10: https://drive.google.com/open?id=1xF9VwNdQkIjFTK37ZaNcTPPKrZblXKh3 | U10: I didn't go for evangelism | V10: No | W10: We weren't able to meet due to unforseen circumstances | X10: https://drive.google.com/open?id=1RHlyRgHA8v5BintTgOIiId4BdmAoibPR
A11: 45714.585 | B11: oyewumimary99@gmail.com | C11: February | D11: Week 2 | E11: Oyewumi Mary.A | F11: University of Ilesa, Osun State | G11: 6 | H11: Greatly | I11: Yes | J11: That at salvation God gave us his life and at consecration we give our self to God | K11: Yes | L11: Our relationship with God is what will determine if God will be able to collect something from us or not | M11: https://drive.google.com/open?id=1MAwzAt8AsBOKUoJPZp3JXQKHJfbzd0SJ, https://drive.google.com/open?id=1SJPPdVt1jo-iGj2c9uI_mae0R6Waq6h5 | N11: No | O11: I don't have yet | P11: Yes | Q11: It's has make me to see all of God and none of me in me living righteous | R11: No | S11: None | T11: https://drive.google.com/open?id=1ZxMlpOJQM_quxCWcw4Gb2arMS39pdCzA | U11: None | V11: No | W11: I don't have any disciple | X11: https://drive.google.com/open?id=1Rgd3X_iQ_xDIBC2lB0vr9l_Vz1JJH6RH
A12: 45714.623 | B12: oyewumimary99@gmail.com | C12: February | D12: Week 3 | E12: Oyewumi Mary Abosede | F12: University of Ilesa, Osun State | G12: 5 | H12: It's has helped to have scheduled time for prayer | I12: Yes | J12: Grace was given to us to lambano : for us to lay hold of | K12: Yes | L12: All the good things that is in Christ I can also do it, that I can love as Christ love and I can also live righteously as christ | M12: https://drive.google.com/open?id=1W9J-1tzhoUtpDOjG1sVnitjFZKAjYQIf | N12: No | O12: I don't have yet | P12: Yes | Q12: It has help me to see that salvation which is suteria mean wholeness that is all encompassing | R12: No | S12: None | T12: https://drive.google.com/open?id=1q9_hgOKjGghK6TKYYQY3XlC300wFbqgq | U12: None | V12: No | W12: I don't have any | X12: https://drive.google.com/open?id=11NMcnj2Spb5gvacYxkkRRMPDtZl86Dgt | Y12: None
A13: 45716.541 | B13: arigbedeiyanuoluwa@gmail.com | C13: February | D13: Week 2 | E13: Arigbede Iyanuoluwa Testimony | F13: Esa-Oke, Osun State | G13: 1 | H13: My praying abilities | I13: No | J13: Let God be in control of your life | K13: Yes | L13: To let God be in control of your life | M13: https://drive.google.com/open?id=1t69rFdZAvjpxMZWJHSoM86ZA3AWhxFGH | N13: No | O13: I am still living under my mum's roof, i have no job | P13: Not Yet | Q13: Not yet | R13: No | S13: None | T13: https://drive.google.com/open?id=1UuS-UnDlm3ignSnTG-mzkiQolGCL_E2g | U13: We have saved some people but they don't later turn up | V13: No | W13: Nothing | X13: https://drive.google.com/open?id=1SHlBKPBhsSmYcw99YbIPyDMOM3-bso5Y | Y13: I do not have an evangelism report yet
A14: 45725.349 | B14: tumininujoyce1@gmail.com | C14: March | D14: Week 1 | E14: O. J Arigbede Esq | F14: Headquarters, Egbe-Idi, Ilesa, Osun State | G14: 3 | H14: It’s been a chance to refire | I14: Yes | J14: The inward man which is our spiritual life is far more important than our outward man which is our physical being. Therefore, pay more attention to taking care of your spiritual life than your physical appearance. | K14: Yes | L14: Same as above | M14: https://drive.google.com/open?id=1O7u37vtn16gjXeYsNkPsNMIKLMiw2xrm | N14: Yes | P14: Not Yet | R14: No | S14: None | T14: https://drive.google.com/open?id=1RY1mttYYPNEmm0l56X7f1rap475--h-f | V14: No | W14: I don’t have any disciple yet | X14: https://drive.google.com/open?id=1EYWY2ZFkh9EdDcC7WXKmJ4rrtObP876U
A15: 45725.368 | B15: arigbedeiyanuoluwa@gmail.com | C15: March | D15: Week 1 | E15: Arigbede Iyanuoluwa Testimony | F15: Headquarters, Egbe-Idi, Ilesa, Osun State | G15: 1 | H15: Yes | I15: No | J15: We should be consistence in prayer | K15: Yes | L15: Pray without seizing | M15: https://drive.google.com/open?id=1EFsIrHPOI8FfbCQQQivyr3o1DgxTIXvB | N15: No | O15: I don't have the financial strength | P15: Not Yet | Q15: It has been impactful | R15: No | S15: None | T15: https://drive.google.com/open?id=1J5-4Tvn-9SH6O4_dGO6XpVgiZn47EZEk | U15: Nothing | V15: No | W15: My house is far from others | X15: https://drive.google.com/open?id=1S_7eU-Z2d3KZGbQKCSk1u84kqTpZR9nN | Y15: Nothing
A16: 45725.535 | B16: Adetumiadefokun@gmail.com | C16: March | D16: Week 1 | E16: Adefokun Adetumi Ebenezer | F16: Ipetu-Ijesha, Osun State | G16: 6 | H16: Helps me to pray better | I16: Yes | J16: That seated in christ jesus | K16: Yes | L16: Am in christ jesus and christ is in me | M16: https://drive.google.com/open?id=1OQPAz9OonK4IKHsjB_7LswHT5rCdHvxIrVS13sIG3ZM | N16: Yes | P16: Yes | Q16: The Gospel is the power of God unto salvation | R16: Yes | S16: 3 | T16: https://drive.google.com/open?id=1dGbnHmC0H4OJn8jnrAJZbgGMqHz4rMiY | V16: Yes | X16: https://drive.google.com/open?id=1qM7UzNSPWbggjijgWDViUFNEzoBaJE-2
A17: 45725.588 | B17: faremolamotunrayoe@gmail.com | C17: March | D17: Week 1 | E17: Akerewusi Motunrayo | F17: University of Ilesa, Osun State | G17: 6 | H17: It's has been helpful | I17: Yes | J17: God's spirit dwells in me | K17: Yes | L17: I learnt that the essence of the teaching is so that I can access all of God | M17: https://drive.google.com/open?id=1gxn9YFiSdyO-qjU5KSLDoqwvAgtH0sRO | N17: Yes | P17: Yes | Q17: It was inspiring | R17: No | S17: None | T17: https://drive.google.com/open?id=1n59BzEGZWU8qRhHJIL7JjvqIBiMaQKSo | V17: No | W17: They traveled | X17: https://drive.google.com/open?id=1FD-c-NUi3Ag6orX5UJgF33YumgTfF-wW
A18: 45725.589 | B18: akerewusioluwadamilare@gmail.com | C18: March | D18: Week 1 | E18: Akerewusi Oluwadamilare Adekusibe | F18: University of Ilesa, Osun State | G18: 5 | H18: Yes. | I18: Yes | J18: We built intimacy with God through His Spirit that's in us. Do much more for your spirit than the physical appearance. | K18: Yes | L18: We built intimacy with God through His Spirit that's in us. Do much more for your spirit than the physical appearance. | M18: https://drive.google.com/open?id=14ckwPJ1QS7UApcpomcvUKkmHjbK3vDJr | N18: No | O18: No for this month. I will very soon. | P18: Not Yet | Q18: Impactful. | R18: No | T18: https://drive.google.com/open?id=1k5hqDageiPVQc1x74se74kRi0qV3CrOo | V18: No | X18: https://drive.google.com/open?id=10Xa-qpWatOCq9zDUCSzR5n98m19fL7_Y | Y18: Sir, you still need to work on evangelism and discipleship spaces.
A19: 45725.592 | B19: oyewumimary99@gmail.com | C19: March | D19: Week 1 | E19: Mary Oyewumi | F19: University of Ilesa, Osun State | G19: 5 | H19: It’s has help me to have consistent prayer life | I19: Yes | J19: Intimacy with God is build in our spirit | K19: Yes | L19: The fact that he dwell in my spirit make him the owner of that house. When God spirit mix with my spirit we become one | M19: https://drive.google.com/open?id=1RP6q0PB7i8FMOA1UbUtYHNtiKxnCLyVf | N19: No | O19: I am rich presently | P19: Yes | Q19: It’s has help me to know that to receive the Holy Spirit is to believe the gospel | R19: No | S19: None | T19: https://drive.google.com/open?id=1QAUdjRbvkukFZwY9eJVN3vvYPf3Lz9Af | V19: No | W19: I don’t have | X19: https://drive.google.com/open?id=1fhcWq4XjUhL9PZXjX8AIqKKEP1IaPwRT
A20: 45725.592 | B20: oniyiderebecca17@gmail.com | C20: March | D20: Week 1 | E20: Oniyide Rebecca | F20: University of Ilesa, Osun State | G20: 4 | H20: It has been edifying moment | I20: Yes | J20: There are two world : the seen world and the unseen world. Both are real. The fact that God is spirit makes him indwell us. The intimacy with God is built in our spirit that where God lives | K20: Yes | L20: There are two world : the seen world and the unseen world. Both are real. The fact that God is spirit makes him indwell us. The intimacy with God is built in our spirit that where God lives | M20: https://drive.google.com/open?id=1Uvxqd_hKkK5UZoJYliXY1ULbpPBhPC9s | N20: Yes | P20: Yes | Q20: Believers are made righteous only by faith in what Christ has done for us | R20: No | T20: https://drive.google.com/open?id=1jDdPOgNvZY5NRva6F9dB1e5tyaXo_n0r | V20: No | W20: They travel, they have a break in school | X20: https://drive.google.com/open?id=1sW8Rl7CtcbVnVBnIKzsCyOeqZsKNzMFD
A21: 45725.596 | B21: olaremiabiola@gmail.com | C21: March | D21: Week 1 | E21: Veronica Abiola Iyabo | F21: University of Ilesa, Osun State | G21: 6 | H21: It has made it consistent | I21: Yes | J21: That the spirit of God in us does not and can never sleep | K21: Yes | L21: The Bible teaching sessions | M21: https://drive.google.com/open?id=1Axiv85gNnwJvEFFbw9n46q2iOEqI8Zlh | N21: No | O21: Financial Constraint | P21: Yes | Q21: It has helped simplified my Christian walk bettr | R21: No | T21: https://drive.google.com/open?id=1i1XEtSuwr7j-f8rN4DzS-yvD8Fj3wjZ9 | V21: No | W21: I don't have any yet | X21: https://drive.google.com/open?id=1O1muEIQyRvYZgB80lEQKVhqRlZvQqzla
A22: 45725.603 | B22: abattayo@gmail.com | C22: March | D22: Week 1 | E22: Abayomi Temitayo Ezekiel | F22: Health Tech Bolorunduro, Ilesa, Osun State | G22: 5 | H22: Yes | I22: Yes | J22: Yes | K22: Yes | L22: Why we study so that we can be full of him | M22: https://drive.google.com/open?id=13VZMcNz_d9zfxbiEQdDSW_xhqPN3CZUc | N22: Yes | P22: Yes | Q22: Yes | R22: No | T22: https://drive.google.com/open?id=1gWLkTehIRI63SHCP6zErMkXnCy_Oq5nn | V22: No | W22: Not around | X22: https://drive.google.com/open?id=1zY2jEKjb-TZHpev-4LVTvsmsEyJHvyQ4
A23: 45731.935 | B23: arigbedeiyanuoluwa@gmail.com | C23: March | D23: Week 2 | E23: Arigbede Iyanuoluwa Testimony | F23: Headquarters, Egbe-Idi, Ilesa, Osun State | G23: 4 | H23: The ability to pray more | I23: No | J23: None | K23: Yes | L23: None | M23: https://drive.google.com/open?id=1T6Sn9THJ1loQSo_KfJxL_4I1uUAHvf-o, https://drive.google.com/open?id=1BMRHK8vov_CjB6qkNT-uwUl7Eep0_i_a | N23: No | O23: Not financially stable | P23: Not Yet | Q23: I have not been listening to it | R23: No | S23: None | T23: https://drive.google.com/open?id=1TuHHrUrkTVabWfwJlgO0cqn6RtNxK6yI | U23: We've saved some people but they are being reluctant | V23: No | W23: Nothing | X23: https://drive.google.com/open?id=1rPW90xtDVbIzOgDo1uOsstFAfAG070EF | Y23: No comment
A24: 45732.349 | B24: poluwaferanmi52@gmail.com | C24: March | D24: Week 2 | E24: Alaba Precious Oluwaferanmi | F24: Health Tech Bolorunduro, Ilesa, Osun State | G24: 4 | H24: It has really my life so far | I24: No | J24: I didn't attend Bible study | K24: No | L24: No | M24: https://drive.google.com/open?id=1dA91mlJTdrIR5VTOWt0niz6o0xCo_i8u | N24: Yes | P24: Not Yet | R24: No | S24: I didn't attend | T24: https://drive.google.com/open?id=18cPj4j8JzrMFdIFLbCvEtOhXAZnrdQNV | V24: No | W24: I didn't have any disciple | X24: https://drive.google.com/open?id=1tEoxTh3ml3eDbMAjvGHLvFYTG30WR4Xk
A25: 45732.62 | B25: oniyiderebecca17@gmail.com | C25: March | D25: Week 2 | E25: Oniyide Rebecca | F25: University of Ilesa, Osun State | G25: 5 | H25: Edifying | I25: Yes | J25: In building intimacy with God the foundation is our heart | K25: Yes | L25: In building intimacy with God the foundation is our heart | M25: https://drive.google.com/open?id=1_hvny773Np7XySVWt9WpvwP24ONc1Dny | N25: No | O25: God will provide | P25: Yes | Q25: God's righteousness is a gift of God to everyone that believe | R25: No | T25: https://drive.google.com/open?id=1NGIs4l2FGgGC4fwGeooUv-044G5WBvUT | V25: No | W25: They travel | X25: https://drive.google.com/open?id=16jMhT2rjRnprLWAo43TwzYiNeAArk7qq
A26: 45732.837 | B26: akerewusioluwadamilare@gmail.com | C26: March | D26: Week 2 | E26: Akerewusi Oluwadamilare Adekusibe | F26: University of Ilesa, Osun State | G26: 5 | H26: Helpful | I26: Yes | J26: Part of what I gained is that the heart is the foundation of building intimacy with God. The state of our hearts as believers are very important in building intimacy with God. | K26: Yes | L26: It's my responsibility to take care of the heart in building intimacy with God. | M26: https://drive.google.com/open?id=1fnE8AJJm1ecSkNwbpLmyI9uB9FfXW7W4, https://drive.google.com/open?id=1RyaDkyzxu9L-8l_4WYSBlfxW-wZ1lRqI | N26: No | O26: I pray for provision. I will surely pay it. | P26: Yes | Q26: Helpful. | R26: No | T26: https://drive.google.com/open?id=18dAcCCTNUFB7ZWeKGEX0lEMwy724-aDj | V26: No | X26: https://drive.google.com/open?id=1uJoPor4K2Ppq0QutOn3N_N3KNTqDGTqX
A27: 45735.761 | B27: akinleyeayomidedeborah@gmail.com | C27: March | D27: Week 1 | E27: Akinleye Ayomide Deborah | F27: Health Tech Bolorunduro, Ilesa, Osun State | G27: 5 | H27: Improve me spiritually | I27: No | J27: I don't attend | K27: Yes | L27: I don't attend | M27: https://drive.google.com/open?id=1xhV2OHrKSMbMLLvPtn_WJXIiDV7loDt3 | N27: No | O27: Financial challenges | P27: Not Yet | R27: Yes | S27: They are all saved | T27: https://drive.google.com/open?id=1KeESJWwW-yVgciLD1OMgxixZUKtzCM9j | V27: No | W27: Not around | X27: https://drive.google.com/open?id=1k2pGuOZpfvWewAWzP3XbUicLLmhgkXVY
A28: 45738.769 | B28: arigbedeiyanuoluwa@gmail.com | C28: March | D28: Week 3 | E28: Arigbede Iyanuoluwa Testimony | F28: Headquarters, Egbe-Idi, Ilesa, Osun State | G28: 1 | H28: I was encourage to pray more | I28: No | J28: Nothing | K28: No | L28: ......... | M28: https://drive.google.com/open?id=1l-ai9fLVjD8D7rjc3JLYcZGgdJqKuoVj | N28: No | O28: No job yet | P28: Not Yet | Q28: Nothing yet | R28: No | S28: None | T28: https://drive.google.com/open?id=1nGRaZDwCpQIPh7GiqL0MJJz7SE2-yX91 | V28: No | W28: Nothing | X28: https://drive.google.com/open?id=1ZJBO5xj3G2PT7cR2UCDB9vf9cRscKMS9
A29: 45739.361 | B29: olaremiabiola@gmail.com | C29: March | D29: Week 2 | E29: Veronica Olaremi Abiola | F29: University of Ilesa, Osun State | G29: 6 | H29: It helped improved and made my prayer life more consistent | I29: Yes | J29: I learnt that my heart is the foundation of building intimacy with God because love comes from the heart not feelings | K29: Yes | L29: I learnt that love starts an intimate relationship but faithfulness sustains it | M29: https://drive.google.com/open?id=1SsB-f_AwN6ao8pshgeTAxPLdvB9CEqOh | N29: No | O29: Financial Constraint | P29: Yes | Q29: It has helped simplify the things of God for me | R29: No | T29: https://drive.google.com/open?id=1FxhUcsV6IVsIYlyC-JIqO_73-IYG5S5F | V29: No | W29: I don’t have any yet | X29: https://drive.google.com/open?id=1nYQuxt2n9I2C-6Uw94YlBCoT5TMYaCNH
A30: 45739.364 | B30: olaremiabiola@gmail.com | C30: March | D30: Week 3 | E30: Veronica Olaremi Abiola | F30: University of Ilesa, Osun State | G30: 6 | H30: It has improved grately | I30: Yes | J30: I learnt that the difference between one believer and another is determined by how faithful we are to God | K30: Yes | L30: That God is not partial but our differences in access to him is dependent on how intimate we are to him | M30: https://drive.google.com/open?id=1y3-z2FrfD0ad8OoBlVWridvLKOu4TbEO | N30: No | O30: Financial constraints | P30: Yes | Q30: Simplify and expounded the word of God to me | R30: No | T30: https://drive.google.com/open?id=1wH87cYaeXA0YnrcjTYozOCSq1yYcIxlD | V30: No | W30: I don’t have any yet | X30: https://drive.google.com/open?id=1uowW9yxbpXTs1B6YTiULyq2ymP9SW38V
A31: 45739.368 | B31: Promsco1996@gmail.com | C31: March | D31: Week 1 | E31: Oluyemi Promise | F31: University of Ilesa, Osun State | G31: 5 | H31: Participating in church prayer has strengthened my faith and trust in God. Hearing others pray and share their testimonies has encouraged me to persevere through difficult times and to believe in God's goodness | I31: No | J31: Not around | K31: Yes | L31: Not around | M31: https://drive.google.com/open?id=1KuEECetjnVJD7pTVnvV0Q7eBj5UfamhP | N31: Yes | P31: Yes | R31: No | T31: https://drive.google.com/open?id=1jVmopRrRQVO3s8IsGr2X8n4MRJBGUB8q | V31: Yes | X31: https://drive.google.com/open?id=1CqwC-oMyF8W-biLeKWrK5urjO0947IOa
A32: 45739.375 | B32: Promsco1996@gmail.com | C32: March | D32: Week 2 | E32: Oluyemi Promise | F32: University of Ilesa, Osun State | G32: 5 | H32: Sense of Belonging Church prayer has given me a sense of belonging to a community of believers. We support and uplift each other, and I feel grateful to be part of a group that shares my values and passions. | I32: Yes | J32: Building intimacy with God starts with knowing Him deeply. Intimacy is cultivated in the heart, not just through head knowledge. The more you know God, the more love is built. Just like any relationship, love grows stronger when you spend quality and quantity time together. To deepen your intimacy with God, focus on: - Spending quality and quantity time with Him - Giving attention and being present - Being appreciative and grateful for His presence - Recognizing and acknowledging His presence in your life By prioritizing these practices, you'll cultivate a richer, more loving relationship with God. | K32: Yes | L32: Building intimacy with God starts with knowing Him deeply. Intimacy is cultivated in the heart, not just through head knowledge. The more you know God, the more love is built. Just like any relationship, love grows stronger when you spend quality and quantity time together. To deepen your intimacy with God, focus on: - Spending quality and quantity time with Him - Giving attention and being present - Being appreciative and grateful for His presence - Recognizing and acknowledging His presence in your life By prioritizing these practices, you'll cultivate a richer, more loving relationship with God. | M32: https://drive.google.com/open?id=10tTlQ230tGLtkBTvaoMwyvLViB8bQ0z4 | N32: No | P32: Not Yet | R32: No | T32: https://drive.google.com/open?id=1KdPVeH2HBT-gTjgl-ASzwdA4p6KdjZf4 | V32: No | X32: https://drive.google.com/open?id=1c-R9Tc3AMwZTLDffUYN3P8HhF6ka5NPQ
A33: 45739.385 | B33: promsco1996@gmail.com | C33: March | D33: Week 3 | E33: Oluyemi Promise | F33: University of Ilesa, Osun State | G33: 5 | H33: Church prayer has helped me cultivate a spirit of gratitude and thanksgiving. I've learned to appreciate God's blessings and goodness in my life, and I've become more mindful of the things that truly matter. | I33: Yes | J33: Access to God is open to all of us. How long you can go in God determine how much of God you can see, intimacy start on the platform of love but faithfulness is the driver and sustainer of intimacy | K33: Yes | L33: Access to God is open to all of us. How long you can go in God determine how much of God you can see, intimacy start on the platform of love but faithfulness is the driver and sustainer of intimacy | M33: https://drive.google.com/open?id=11b5HnQh633A7twDB7oR_vNf6aD5baspv | N33: No | P33: Yes | Q33: I've gained a deeper understanding of God's character and nature. I've learned to see Him as a loving Father, a gracious Redeemer, and a faithful Friend. This understanding has transformed my relationship with God and has given me a newfound sense of purpose and meaning. | R33: No | T33: https://drive.google.com/open?id=1GgbyCVO5vWRfdX1ylhwwwKOIgvj-iZok | V33: No | X33: https://drive.google.com/open?id=1rq2Al0tjqkqjPsADiGbyxzq7Heo7dKBZ
A34: 45739.421 | B34: akinleyeayomidedeborah@gmail.com | C34: March | D34: Week 2 | E34: Akinleye Ayomide Deborah | F34: Health Tech Bolorunduro, Ilesa, Osun State | G34: 6 | H34: Improve me spiritually | I34: No | J34: Don't attend | K34: Yes | L34: Don't attend | M34: https://drive.google.com/open?id=15vcRSob0Y807oJnKwpWS6gW9GEAyB7Nd | N34: No | O34: Financial challenges | P34: Yes | Q34: Impact me more and encourage me to known Christ more. | R34: Yes | S34: 2 | T34: https://drive.google.com/open?id=1IHPRoUV0AfGSXgxgVqbBZp5jJkVvCW9m | V34: No | W34: Not around | X34: https://drive.google.com/open?id=1pyloG3EnwsUxB11ky1Fy5XnBrlel_PMl
A35: 45742.594 | B35: oyewumimary99@gmail.com | C35: March | D35: Week 2 | E35: Oyewumi Mary Abosede | F35: University of Ilesa, Osun State | G35: 5 | H35: It has help me to have personal prayer life | I35: Yes | J35: In building intimacy with God the foundation which is the most important is our heart and the state of our heart determines how our intimacy with God is going to look like. | K35: Yes | L35: In building intimacy we have to be careful with what we're building intimacy with We need to pay attention to the state of our heart because what is inside our heart is what will determine what is outside that we need to concentrate on the man inside than the man outside. | M35: https://drive.google.com/open?id=1__mnh8Ox-AB9NZJ3I1prK34euUJm-9RI | N35: No | O35: No | P35: Yes | Q35: It has made me to see that gospel is believing in the grace of our Lord Jesus Christ and it's the gospel that show us how a man can be right with God | R35: No | S35: None | T35: https://drive.google.com/open?id=1VbOWj6zMOd_tTDekJauOz4kbC2qEnOj2 | V35: No | W35: I don't have | X35: https://drive.google.com/open?id=1GIsVW1Wev5O1073BNMxGhAWhJgORltI7
A36: 45742.603 | B36: oyewumimary99@gmail.com | C36: March | D36: Week 3 | E36: Oyewumi Mary Abosede | F36: University of Ilesa, Osun State | G36: 4 | H36: It has help me to have personal relationship with the father at an early hour | I36: No | J36: I wasn't around | K36: Yes | L36: I wasn't around | M36: https://drive.google.com/open?id=17j25-Wg1iDmKstm45ziiy-G1rcocSL-d | N36: No | O36: No | P36: Yes | Q36: It has help me to see that gospel has been in existence from the old testament and it was made clear in the new testament and that what was preached to Abraham was the gospel | R36: No | S36: None | T36: https://drive.google.com/open?id=1G0F_v-Qz9M0uVfn4rQNuGrV-rKIknJmM | V36: No | W36: I don't have any | X36: https://drive.google.com/open?id=1a1hEHwa1m-Som0L77atUhvrS04GPNWKG
A37: 45745.697 | B37: owolabimary2208@gmail.com | C37: March | D37: Week 1 | E37: Owolabi Mary | F37: Health Tech Bolorunduro, Ilesa, Osun State | G37: 4 | H37: It helps my consistency in praying | I37: Yes | J37: We build intimacy with God so that will can access all of God | K37: Yes | L37: Pastor's teaching | M37: https://drive.google.com/open?id=1socCaR4IqmVv1MArVb2SNA6gXvUinKZ3 | N37: Yes | P37: Yes | Q37: It increases my understanding of the Grace of God | R37: Yes | S37: Nill | T37: https://drive.google.com/open?id=1xSnz_y9qMBeR69pwgJheLn3Qa899nQSo | V37: Yes | X37: https://drive.google.com/open?id=1-u9GaNLr8tMRwIkrl_-OIPfEEPOAtIU0
A38: 45745.711 | B38: owolabimary2208@gmail.com | C38: March | D38: Week 2 | E38: Owolabi Mary Blessing | F38: Health Tech Bolorunduro, Ilesa, Osun State | G38: 4 | H38: To be more conscious of prayer | I38: Yes | J38: My heart is the foundation of building intimacy with God | K38: Yes | L38: Christ should be in your heart not only on your lips | M38: https://drive.google.com/open?id=152tgTl-0IgtgKh0K2glttLEaazoSHN5h | N38: Yes | P38: Yes | Q38: It increases my knowledge of the Grace of God in Christ | R38: Yes | S38: 2 | T38: https://drive.google.com/open?id=1OjLudhvfaEPsRFubD1UNzUZSWfdOSFpT | V38: Yes | X38: https://drive.google.com/open?id=1kFYkTq3y8i-HmmmH1omvqcgT2qEPMtWV
A39: 45745.723 | B39: owolabimary2208@gmail.com | C39: March | D39: Week 3 | E39: Owolabi Mary Blessing | F39: Health Tech Bolorunduro, Ilesa, Osun State | G39: 4 | H39: It helps my consecration to prayer | I39: Yes | J39: How long and how deep you can go in God it depend on your level of intimacy with Him | K39: Yes | L39: If you are not faithful with little more can not entrusted to your hands. | M39: https://drive.google.com/open?id=1NEuEiUyIOp17O_ZNK_LiYN1qNkYw7FxF | N39: Yes | P39: Yes | Q39: It inspires me to be grateful for His grace | R39: Yes | S39: Nill | T39: https://drive.google.com/open?id=1EGz-w2s43DE7FqwFoxrkivB5_EPuTlwJ | V39: Yes | X39: https://drive.google.com/open?id=1Jx4h0BHvNJVU_boS4aoUXvz2D9rW0mGZ
A40: 45745.901 | B40: akerewusioluwadamilare@gmail.com | C40: March | D40: Week 3 | E40: Akerewusi Oluwadamilare Adekusibe | F40: University of Ilesa, Osun State | G40: 5 | H40: Helpful. | I40: Yes | J40: Faithfulness. In building intimacy with God faithfulness is needed. | K40: Yes | L40: God is faithful. God also requires faithfulness from us as his children. | M40: https://drive.google.com/open?id=1nqIp7BeTKF6i2qGqUZYdC0Ib24ZDAgFL, https://drive.google.com/open?id=1nnIFpHiZayPBcpTk75NHZqFHBJ_KddXP | N40: Yes | P40: Yes | Q40: Helpful. | R40: Yes | T40: https://drive.google.com/open?id=1Ti1ALXH517avSri0B2-165aRyxSe4WSD | V40: Yes | X40: https://drive.google.com/open?id=1I3lNoFPsfxtqzuueB8dp3ZZOYa8UWGQb
...

Sheet Individual Submission
A1: S/N | B1: Email Address | C1: Name | D1: Branch | E1: Jan | F1: Feb | G1: Mar | H1: Apr | I1: May | J1: Jun | K1: Jul | L1: Aug | M1: Sep | N1: Oct | O1: Nov | P1: Dec | Q1: Total per Worker
A2: 1 | B2: oniyiderebecca17@gmail.com | C2: =_xlfn.XLOOKUP($B2, MainDB[Email Address], MainDB[Worker''s Full Name],,0) -> Oniyide Rebecca | D2: =_xlfn.XLOOKUP($B2, MainDB[Email Address], MainDB[Branch],,0) -> University of Ilesa, Osun State | E2: =COUNTIFS(MainDB[Email Address],'Individual Submission'!$B2,MainDB[Month], "January") -> 1 | F2: =COUNTIFS(MainDB[Email Address],'Individual Submission'!$B2,MainDB[Month], "February") -> 0 | G2: =COUNTIFS(MainDB[Email Address],'Individual Submission'!$B2,MainDB[Month], "March") -> 4 | H2: =COUNTIFS(MainDB[Email Address],'Individual Submission'!$B2,MainDB[Month], "April") -> 0 | I2: =COUNTIFS(MainDB[Email Address],'Individual Submission'!$B2,MainDB[Month], "May") -> 0 | J2: =COUNTIFS(MainDB[Email Address],'Individual Submission'!$B2,MainDB[Month], "June") -> 2 | K2: =COUNTIFS(MainDB[Email Address],'Individual Submission'!$B2,MainDB[Month], "July") -> 0 | L2: =COUNTIFS(MainDB[Email Address],'Individual Submission'!$B2,MainDB[Month], "August") -> 0 | M2: =COUNTIFS(MainDB[Email Address],'Individual Submission'!$B2,MainDB[Month], "September") -> 0 | N2: =COUNTIFS(MainDB[Email Address],'Individual Submission'!$B2,MainDB[Month], "October") -> 0 | O2: =COUNTIFS(MainDB[Email Address],'Individual Submission'!$B2,MainDB[Month], "November") -> 0 | P2: =COUNTIFS(MainDB[Email Address],'Individual Submission'!$B2,MainDB[Month], "December") -> 0 | Q2: =SUM(E2:P2) -> 7
A3: 2 | B3: adetumiadefokun@gmail.com | C3: =_xlfn.XLOOKUP($B3, MainDB[Email Address], MainDB[Worker''s Full Name],,0) -> Adefokun Adetumi Ebenezer | D3: =_xlfn.XLOOKUP($B3, MainDB[Email Address], MainDB[Branch],,0) -> Ipetu-Ijesha, Osun State | E3: =COUNTIFS(MainDB[Email Address],'Individual Submission'!$B3,MainDB[Month], "January") -> 1 | F3: =COUNTIFS(MainDB[Email Address],'Individual Submission'!$B3,MainDB[Month], "February") -> 0 | G3: =COUNTIFS(MainDB[Email Address],'Individual Submission'!$B3,MainDB[Month], "March") -> 1 | H3: =COUNTIFS(MainDB[Email Address],'Individual Submission'!$B3,MainDB[Month], "April") -> 0 | I3: =COUNTIFS(MainDB[Email Address],'Individual Submission'!$B3,MainDB[Month], "May") -> 0 | J3: =COUNTIFS(MainDB[Email Address],'Individual Submission'!$B3,MainDB[Month], "June") -> 0 | K3: =COUNTIFS(MainDB[Email Address],'Individual Submission'!$B3,MainDB[Month], "July") -> 0 | L3: =COUNTIFS(MainDB[Email Address],'Individual Submission'!$B3,MainDB[Month], "August") -> 0 | M3: =COUNTIFS(MainDB[Email Address],'Individual Submission'!$B3,MainDB[Month], "September") -> 1 | N3: =COUNTIFS(MainDB[Email Address],'Individual Submission'!$B3,MainDB[Month], "October") -> 0 | O3: =COUNTIFS(MainDB[Email Address],'Individual Submission'!$B3,MainDB[Month], "November") -> 1 | P3: =COUNTIFS(MainDB[Email Address],'Individual Submission'!$B3,MainDB[Month], "December") -> 0 | Q3: =SUM(E3:P3) -> 4
A4: 3 | B4: akerewusioluwadamilare@gmail.com | C4: =_xlfn.XLOOKUP($B4, MainDB[Email Address], MainDB[Worker''s Full Name],,0) -> Akerewusi Oluwadamilare | D4: =_xlfn.XLOOKUP($B4, MainDB[Email Address], MainDB[Branch],,0) -> University of Ilesa, Osun State | E4: =COUNTIFS(MainDB[Email Address],'Individual Submission'!$B4,MainDB[Month], "January") -> 1 | F4: =COUNTIFS(MainDB[Email Address],'Individual Submission'!$B4,MainDB[Month], "February") -> 0 | G4: =COUNTIFS(MainDB[Email Address],'Individual Submission'!$B4,MainDB[Month], "March") -> 5 | H4: =COUNTIFS(MainDB[Email Address],'Individual Submission'!$B4,MainDB[Month], "April") -> 1 | I4: =COUNTIFS(MainDB[Email Address],'Individual Submission'!$B4,MainDB[Month], "May") -> 0 | J4: =COUNTIFS(MainDB[Email Address],'Individual Submission'!$B4,MainDB[Month], "June") -> 3 | K4: =COUNTIFS(MainDB[Email Address],'Individual Submission'!$B4,MainDB[Month], "July") -> 0 | L4: =COUNTIFS(MainDB[Email Address],'Individual Submission'!$B4,MainDB[Month], "August") -> 0 | M4: =COUNTIFS(MainDB[Email Address],'Individual Submission'!$B4,MainDB[Month], "September") -> 1 | N4: =COUNTIFS(MainDB[Email Address],'Individual Submission'!$B4,MainDB[Month], "October") -> 1 | O4: =COUNTIFS(MainDB[Email Address],'Individual Submission'!$B4,MainDB[Month], "November") -> 1 | P4: =COUNTIFS(MainDB[Email Address],'Individual Submission'!$B4,MainDB[Month], "December") -> 0 | Q4: =SUM(E4:P4) -> 13
A5: 4 | B5: akinleyeayomidedeborah@gmail.com | C5: =_xlfn.XLOOKUP($B5, MainDB[Email Address], MainDB[Worker''s Full Name],,0) -> Akinleye Ayomide Deborah | D5: =_xlfn.XLOOKUP($B5, MainDB[Email Address], MainDB[Branch],,0) -> Health Tech Bolorunduro, Ilesa, Osun State | E5: =COUNTIFS(MainDB[Email Address],'Individual Submission'!$B5,MainDB[Month], "January") -> 0 | F5: =COUNTIFS(MainDB[Email Address],'Individual Submission'!$B5,MainDB[Month], "February") -> 1 | G5: =COUNTIFS(MainDB[Email Address],'Individual Submission'!$B5,MainDB[Month], "March") -> 2 | H5: =COUNTIFS(MainDB[Email Address],'Individual Submission'!$B5,MainDB[Month], "April") -> 0 | I5: =COUNTIFS(MainDB[Email Address],'Individual Submission'!$B5,MainDB[Month], "May") -> 0 | J5: =COUNTIFS(MainDB[Email Address],'Individual Submission'!$B5,MainDB[Month], "June") -> 3 | K5: =COUNTIFS(MainDB[Email Address],'Individual Submission'!$B5,MainDB[Month], "July") -> 0 | L5: =COUNTIFS(MainDB[Email Address],'Individual Submission'!$B5,MainDB[Month], "August") -> 0 | M5: =COUNTIFS(MainDB[Email Address],'Individual Submission'!$B5,MainDB[Month], "September") -> 0 | N5: =COUNTIFS(MainDB[Email Address],'Individual Submission'!$B5,MainDB[Month], "October") -> 0 | O5: =COUNTIFS(MainDB[Email Address],'Individual Submission'!$B5,MainDB[Month], "November") -> 1 | P5: =COUNTIFS(MainDB[Email Address],'Individual Submission'!$B5,MainDB[Month], "December") -> 0 | Q5: =SUM(E5:P5) -> 7
A6: 5 | B6: lorleybee@gmail.com | C6: =_xlfn.XLOOKUP($B6, MainDB[Email Address], MainDB[Worker''s Full Name],,0) -> Durodola Ololade | D6: =_xlfn.XLOOKUP($B6, MainDB[Email Address], MainDB[Branch],,0) -> Esa-Oke, Osun State | E6: =COUNTIFS(MainDB[Email Address],'Individual Submission'!$B6,MainDB[Month], "January") -> 1 | F6: =COUNTIFS(MainDB[Email Address],'Individual Submission'!$B6,MainDB[Month], "February") -> 0 | G6: =COUNTIFS(MainDB[Email Address],'Individual Submission'!$B6,MainDB[Month], "March") -> 0 | H6: =COUNTIFS(MainDB[Email Address],'Individual Submission'!$B6,MainDB[Month], "April") -> 0 | I6: =COUNTIFS(MainDB[Email Address],'Individual Submission'!$B6,MainDB[Month], "May") -> 0 | J6: =COUNTIFS(MainDB[Email Address],'Individual Submission'!$B6,MainDB[Month], "June") -> 0 | K6: =COUNTIFS(MainDB[Email Address],'Individual Submission'!$B6,MainDB[Month], "July") -> 0 | L6: =COUNTIFS(MainDB[Email Address],'Individual Submission'!$B6,MainDB[Month], "August") -> 0 | M6: =COUNTIFS(MainDB[Email Address],'Individual Submission'!$B6,MainDB[Month], "September") -> 2 | N6: =COUNTIFS(MainDB[Email Address],'Individual Submission'!$B6,MainDB[Month], "October") -> 0 | O6: =COUNTIFS(MainDB[Email Address],'Individual Submission'!$B6,MainDB[Month], "November") -> 1 | P6: =COUNTIFS(MainDB[Email Address],'Individual Submission'!$B6,MainDB[Month], "December") -> 0 | Q6: =SUM(E6:P6) -> 4
A7: 6 | B7: ogundareolamideemmanuel@gmail.com | C7: =_xlfn.XLOOKUP($B7, MainDB[Email Address], MainDB[Worker''s Full Name],,0) -> Ogundare Olamide Emmanuel | D7: =_xlfn.XLOOKUP($B7, MainDB[Email Address], MainDB[Branch],,0) -> Headquarters, Egbe-Idi, Ilesa, Osun State | E7: =COUNTIFS(MainDB[Email Address],'Individual Submission'!$B7,MainDB[Month], "January") -> 1 | F7: =COUNTIFS(MainDB[Email Address],'Individual Submission'!$B7,MainDB[Month], "February") -> 1 | G7: =COUNTIFS(MainDB[Email Address],'Individual Submission'!$B7,MainDB[Month], "March") -> 0 | H7: =COUNTIFS(MainDB[Email Address],'Individual Submission'!$B7,MainDB[Month], "April") -> 0 | I7: =COUNTIFS(MainDB[Email Address],'Individual Submission'!$B7,MainDB[Month], "May") -> 0 | J7: =COUNTIFS(MainDB[Email Address],'Individual Submission'!$B7,MainDB[Month], "June") -> 0 | K7: =COUNTIFS(MainDB[Email Address],'Individual Submission'!$B7,MainDB[Month], "July") -> 0 | L7: =COUNTIFS(MainDB[Email Address],'Individual Submission'!$B7,MainDB[Month], "August") -> 0 | M7: =COUNTIFS(MainDB[Email Address],'Individual Submission'!$B7,MainDB[Month], "September") -> 0 | N7: =COUNTIFS(MainDB[Email Address],'Individual Submission'!$B7,MainDB[Month], "October") -> 0 | O7: =COUNTIFS(MainDB[Email Address],'Individual Submission'!$B7,MainDB[Month], "November") -> 0 | P7: =COUNTIFS(MainDB[Email Address],'Individual Submission'!$B7,MainDB[Month], "December") -> 0 | Q7: =SUM(E7:P7) -> 2
A8: 7 | B8: abattayo@gmail.com | C8: =_xlfn.XLOOKUP($B8, MainDB[Email Address], MainDB[Worker''s Full Name],,0) -> Abayomi Temitayo Ezekiel | D8: =_xlfn.XLOOKUP($B8, MainDB[Email Address], MainDB[Branch],,0) -> Health Tech Bolorunduro, Ilesa, Osun State | E8: =COUNTIFS(MainDB[Email Address],'Individual Submission'!$B8,MainDB[Month], "January") -> 0 | F8: =COUNTIFS(MainDB[Email Address],'Individual Submission'!$B8,MainDB[Month], "February") -> 1 | G8: =COUNTIFS(MainDB[Email Address],'Individual Submission'!$B8,MainDB[Month], "March") -> 3 | H8: =COUNTIFS(MainDB[Email Address],'Individual Submission'!$B8,MainDB[Month], "April") -> 0 | I8: =COUNTIFS(MainDB[Email Address],'Individual Submission'!$B8,MainDB[Month], "May") -> 0 | J8: =COUNTIFS(MainDB[Email Address],'Individual Submission'!$B8,MainDB[Month], "June") -> 1 | K8: =COUNTIFS(MainDB[Email Address],'Individual Submission'!$B8,MainDB[Month], "July") -> 0 | L8: =COUNTIFS(MainDB[Email Address],'Individual Submission'!$B8,MainDB[Month], "August") -> 0 | M8: =COUNTIFS(MainDB[Email Address],'Individual Submission'!$B8,MainDB[Month], "September") -> 0 | N8: =COUNTIFS(MainDB[Email Address],'Individual Submission'!$B8,MainDB[Month], "October") -> 0 | O8: =COUNTIFS(MainDB[Email Address],'Individual Submission'!$B8,MainDB[Month], "November") -> 0 | P8: =COUNTIFS(MainDB[Email Address],'Individual Submission'!$B8,MainDB[Month], "December") -> 0 | Q8: =SUM(E8:P8) -> 5
A9: 8 | B9: oyewumimary99@gmail.com | C9: =_xlfn.XLOOKUP($B9, MainDB[Email Address], MainDB[Worker''s Full Name],,0) -> Oyewumi Mary.A | D9: =_xlfn.XLOOKUP($B9, MainDB[Email Address], MainDB[Branch],,0) -> University of Ilesa, Osun State | E9: =COUNTIFS(MainDB[Email Address],'Individual Submission'!$B9,MainDB[Month], "January") -> 0 | F9: =COUNTIFS(MainDB[Email Address],'Individual Submission'!$B9,MainDB[Month], "February") -> 3 | G9: =COUNTIFS(MainDB[Email Address],'Individual Submission'!$B9,MainDB[Month], "March") -> 4 | H9: =COUNTIFS(MainDB[Email Address],'Individual Submission'!$B9,MainDB[Month], "April") -> 2 | I9: =COUNTIFS(MainDB[Email Address],'Individual Submission'!$B9,MainDB[Month], "May") -> 0 | J9: =COUNTIFS(MainDB[Email Address],'Individual Submission'!$B9,MainDB[Month], "June") -> 4 | K9: =COUNTIFS(MainDB[Email Address],'Individual Submission'!$B9,MainDB[Month], "July") -> 0 | L9: =COUNTIFS(MainDB[Email Address],'Individual Submission'!$B9,MainDB[Month], "August") -> 0 | M9: =COUNTIFS(MainDB[Email Address],'Individual Submission'!$B9,MainDB[Month], "September") -> 2 | N9: =COUNTIFS(MainDB[Email Address],'Individual Submission'!$B9,MainDB[Month], "October") -> 0 | O9: =COUNTIFS(MainDB[Email Address],'Individual Submission'!$B9,MainDB[Month], "November") -> 1 | P9: =COUNTIFS(MainDB[Email Address],'Individual Submission'!$B9,MainDB[Month], "December") -> 0 | Q9: =SUM(E9:P9) -> 16
A10: 9 | B10: arigbedeiyanuoluwa@gmail.com | C10: =_xlfn.XLOOKUP($B10, MainDB[Email Address], MainDB[Worker''s Full Name],,0) -> Arigbede Iyanuoluwa Testimony | D10: =_xlfn.XLOOKUP($B10, MainDB[Email Address], MainDB[Branch],,0) -> Esa-Oke, Osun State | E10: =COUNTIFS(MainDB[Email Address],'Individual Submission'!$B10,MainDB[Month], "January") -> 0 | F10: =COUNTIFS(MainDB[Email Address],'Individual Submission'!$B10,MainDB[Month], "February") -> 1 | G10: =COUNTIFS(MainDB[Email Address],'Individual Submission'!$B10,MainDB[Month], "March") -> 4 | H10: =COUNTIFS(MainDB[Email Address],'Individual Submission'!$B10,MainDB[Month], "April") -> 0 | I10: =COUNTIFS(MainDB[Email Address],'Individual Submission'!$B10,MainDB[Month], "May") -> 0 | J10: =COUNTIFS(MainDB[Email Address],'Individual Submission'!$B10,MainDB[Month], "June") -> 0 | K10: =COUNTIFS(MainDB[Email Address],'Individual Submission'!$B10,MainDB[Month], "July") -> 0 | L10: =COUNTIFS(MainDB[Email Address],'Individual Submission'!$B10,MainDB[Month], "August") -> 0 | M10: =COUNTIFS(MainDB[Email Address],'Individual Submission'!$B10,MainDB[Month], "September") -> 0 | N10: =COUNTIFS(MainDB[Email Address],'Individual Submission'!$B10,MainDB[Month], "October") -> 0 | O10: =COUNTIFS(MainDB[Email Address],'Individual Submission'!$B10,MainDB[Month], "November") -> 0 | P10: =COUNTIFS(MainDB[Email Address],'Individual Submission'!$B10,MainDB[Month], "December") -> 0 | Q10: =SUM(E10:P10) -> 5
A11: 10 | B11: tumininujoyce1@gmail.com | C11: =_xlfn.XLOOKUP($B11, MainDB[Email Address], MainDB[Worker''s Full Name],,0) -> O. J Arigbede Esq | D11: =_xlfn.XLOOKUP($B11, MainDB[Email Address], MainDB[Branch],,0) -> Headquarters, Egbe-Idi, Ilesa, Osun State | E11: =COUNTIFS(MainDB[Email Address],'Individual Submission'!$B11,MainDB[Month], "January") -> 0 | F11: =COUNTIFS(MainDB[Email Address],'Individual Submission'!$B11,MainDB[Month], "February") -> 0 | G11: =COUNTIFS(MainDB[Email Address],'Individual Submission'!$B11,MainDB[Month], "March") -> 1 | H11: =COUNTIFS(MainDB[Email Address],'Individual Submission'!$B11,MainDB[Month], "April") -> 0 | I11: =COUNTIFS(MainDB[Email Address],'Individual Submission'!$B11,MainDB[Month], "May") -> 0 | J11: =COUNTIFS(MainDB[Email Address],'Individual Submission'!$B11,MainDB[Month], "June") -> 1 | K11: =COUNTIFS(MainDB[Email Address],'Individual Submission'!$B11,MainDB[Month], "July") -> 0 | L11: =COUNTIFS(MainDB[Email Address],'Individual Submission'!$B11,MainDB[Month], "August") -> 0 | M11: =COUNTIFS(MainDB[Email Address],'Individual Submission'!$B11,MainDB[Month], "September") -> 1 | N11: =COUNTIFS(MainDB[Email Address],'Individual Submission'!$B11,MainDB[Month], "October") -> 0 | O11: =COUNTIFS(MainDB[Email Address],'Individual Submission'!$B11,MainDB[Month], "November") -> 1 | P11: =COUNTIFS(MainDB[Email Address],'Individual Submission'!$B11,MainDB[Month], "December") -> 0 | Q11: =SUM(E11:P11) -> 4
A12: 11 | B12: faremolamotunrayoe@gmail.com | C12: =_xlfn.XLOOKUP($B12, MainDB[Email Address], MainDB[Worker''s Full Name],,0) -> Akerewusi Motunrayo | D12: =_xlfn.XLOOKUP($B12, MainDB[Email Address], MainDB[Branch],,0) -> University of Ilesa, Osun State | E12: =COUNTIFS(MainDB[Email Address],'Individual Submission'!$B12,MainDB[Month], "January") -> 0 | F12: =COUNTIFS(MainDB[Email Address],'Individual Submission'!$B12,MainDB[Month], "February") -> 0 | G12: =COUNTIFS(MainDB[Email Address],'Individual Submission'!$B12,MainDB[Month], "March") -> 1 | H12: =COUNTIFS(MainDB[Email Address],'Individual Submission'!$B12,MainDB[Month], "April") -> 0 | I12: =COUNTIFS(MainDB[Email Address],'Individual Submission'!$B12,MainDB[Month], "May") -> 0 | J12: =COUNTIFS(MainDB[Email Address],'Individual Submission'!$B12,MainDB[Month], "June") -> 3 | K12: =COUNTIFS(MainDB[Email Address],'Individual Submission'!$B12,MainDB[Month], "July") -> 0 | L12: =COUNTIFS(MainDB[Email Address],'Individual Submission'!$B12,MainDB[Month], "August") -> 0 | M12: =COUNTIFS(MainDB[Email Address],'Individual Submission'!$B12,MainDB[Month], "September") -> 1 | N12: =COUNTIFS(MainDB[Email Address],'Individual Submission'!$B12,MainDB[Month], "October") -> 0 | O12: =COUNTIFS(MainDB[Email Address],'Individual Submission'!$B12,MainDB[Month], "November") -> 1 | P12: =COUNTIFS(MainDB[Email Address],'Individual Submission'!$B12,MainDB[Month], "December") -> 0 | Q12: =SUM(E12:P12) -> 6
A13: 12 | B13: olaremiabiola@gmail.com | C13: =_xlfn.XLOOKUP($B13, MainDB[Email Address], MainDB[Worker''s Full Name],,0) -> Veronica Abiola Iyabo | D13: =_xlfn.XLOOKUP($B13, MainDB[Email Address], MainDB[Branch],,0) -> University of Ilesa, Osun State | E13: =COUNTIFS(MainDB[Email Address],'Individual Submission'!$B13,MainDB[Month], "January") -> 0 | F13: =COUNTIFS(MainDB[Email Address],'Individual Submission'!$B13,MainDB[Month], "February") -> 0 | G13: =COUNTIFS(MainDB[Email Address],'Individual Submission'!$B13,MainDB[Month], "March") -> 3 | H13: =COUNTIFS(MainDB[Email Address],'Individual Submission'!$B13,MainDB[Month], "April") -> 0 | I13: =COUNTIFS(MainDB[Email Address],'Individual Submission'!$B13,MainDB[Month], "May") -> 0 | J13: =COUNTIFS(MainDB[Email Address],'Individual Submission'!$B13,MainDB[Month], "June") -> 5 | K13: =COUNTIFS(MainDB[Email Address],'Individual Submission'!$B13,MainDB[Month], "July") -> 0 | L13: =COUNTIFS(MainDB[Email Address],'Individual Submission'!$B13,MainDB[Month], "August") -> 0 | M13: =COUNTIFS(MainDB[Email Address],'Individual Submission'!$B13,MainDB[Month], "September") -> 0 | N13: =COUNTIFS(MainDB[Email Address],'Individual Submission'!$B13,MainDB[Month], "October") -> 0 | O13: =COUNTIFS(MainDB[Email Address],'Individual Submission'!$B13,MainDB[Month], "November") -> 0 | P13: =COUNTIFS(MainDB[Email Address],'Individual Submission'!$B13,MainDB[Month], "December") -> 0 | Q13: =SUM(E13:P13) -> 8
... A17: 16 | B17: adefokuntimileyin@gmail.com | C17: =_xlfn.XLOOKUP($B17, MainDB[Email Address], MainDB[Worker''s Full Name],,0) -> Adefokun Timileyin Victoria | D17: =_xlfn.XLOOKUP($B17, MainDB[Email Address], MainDB[Branch],,0) -> Ipetu-Ijesha, Osun State | E17: =COUNTIFS(MainDB[Email Address],'Individual Submission'!$B17,MainDB[Month], "January") -> 0 | F17: =COUNTIFS(MainDB[Email Address],'Individual Submission'!$B17,MainDB[Month], "February") -> 0 | G17: =COUNTIFS(MainDB[Email Address],'Individual Submission'!$B17,MainDB[Month], "March") -> 1 | H17: =COUNTIFS(MainDB[Email Address],'Individual Submission'!$B17,MainDB[Month], "April") -> 0 | I17: =COUNTIFS(MainDB[Email Address],'Individual Submission'!$B17,MainDB[Month], "May") -> 0 | J17: =COUNTIFS(MainDB[Email Address],'Individual Submission'!$B17,MainDB[Month], "June") -> 0 | K17: =COUNTIFS(MainDB[Email Address],'Individual Submission'!$B17,MainDB[Month], "July") -> 0 | L17: =COUNTIFS(MainDB[Email Address],'Individual Submission'!$B17,MainDB[Month], "August") -> 0 | M17: =COUNTIFS(MainDB[Email Address],'Individual Submission'!$B17,MainDB[Month], "September") -> 0 | N17: =COUNTIFS(MainDB[Email Address],'Individual Submission'!$B17,MainDB[Month], "October") -> 0 | O17: =COUNTIFS(MainDB[Email Address],'Individual Submission'!$B17,MainDB[Month], "November") -> 0 | P17: =COUNTIFS(MainDB[Email Address],'Individual Submission'!$B17,MainDB[Month], "December") -> 0 | Q17: =SUM(E17:P17) -> 1

Sheet Branch Submission
A1: Branch | B1: Jan | C1: Feb | D1: Mar | E1: Apr | F1: May | G1: Jun | H1: Jul | I1: Aug | J1: Sep | K1: Oct | L1: Nov | M1: Dec | N1: Total per Branch
A2: University Of Ilesa, Osun State | B2: =COUNTIFS(MainDB[Branch],'Branch Submission'!$A2,MainDB[Month], "January") -> 2 | C2: =COUNTIFS(MainDB[Branch],'Branch Submission'!$A2,MainDB[Month], "February") -> 3 | D2: =COUNTIFS(MainDB[Branch],'Branch Submission'!$A2,MainDB[Month], "March") -> 20 | E2: =COUNTIFS(MainDB[Branch],'Branch Submission'!$A2,MainDB[Month], "April") -> 3 | F2: =COUNTIFS(MainDB[Branch],'Branch Submission'!$A2,MainDB[Month], "May") -> 0 | G2: =COUNTIFS(MainDB[Branch],'Branch Submission'!$A2,MainDB[Month], "June") -> 12 | H2: =COUNTIFS(MainDB[Branch],'Branch Submission'!$A2,MainDB[Month], "July") -> 0 | I2: =COUNTIFS(MainDB[Branch],'Branch Submission'!$A2,MainDB[Month], "August") -> 0 | J2: =COUNTIFS(MainDB[Branch],'Branch Submission'!$A2,MainDB[Month], "September") -> 4 | K2: =COUNTIFS(MainDB[Branch],'Branch Submission'!$A2,MainDB[Month], "October") -> 1 | L2: =COUNTIFS(MainDB[Branch],'Branch Submission'!$A2,MainDB[Month], "November") -> 3 | M2: =COUNTIFS(MainDB[Branch],'Branch Submission'!$A2,MainDB[Month], "December") -> 0 | N2: =SUM(B2:M2) -> 48
A3: Ipetu-Ijesha, Osun State | B3: =COUNTIFS(MainDB[Branch],'Branch Submission'!$A3,MainDB[Month], "January") -> 1 | C3: =COUNTIFS(MainDB[Branch],'Branch Submission'!$A3,MainDB[Month], "February") -> 0 | D3: =COUNTIFS(MainDB[Branch],'Branch Submission'!$A3,MainDB[Month], "March") -> 2 | E3: =COUNTIFS(MainDB[Branch],'Branch Submission'!$A3,MainDB[Month], "April") -> 0 | F3: =COUNTIFS(MainDB[Branch],'Branch Submission'!$A3,MainDB[Month], "May") -> 0 | G3: =COUNTIFS(MainDB[Branch],'Branch Submission'!$A3,MainDB[Month], "June") -> 0 | H3: =COUNTIFS(MainDB[Branch],'Branch Submission'!$A3,MainDB[Month], "July") -> 0 | I3: =COUNTIFS(MainDB[Branch],'Branch Submission'!$A3,MainDB[Month], "August") -> 0 | J3: =COUNTIFS(MainDB[Branch],'Branch Submission'!$A3,MainDB[Month], "September") -> 0 | K3: =COUNTIFS(MainDB[Branch],'Branch Submission'!$A3,MainDB[Month], "October") -> 0 | L3: =COUNTIFS(MainDB[Branch],'Branch Submission'!$A3,MainDB[Month], "November") -> 0 | M3: =COUNTIFS(MainDB[Branch],'Branch Submission'!$A3,MainDB[Month], "December") -> 0 | N3: =SUM(B3:M3) -> 3
A4: Health Tech Bolorunduro, Ilesa, Osun State | B4: =COUNTIFS(MainDB[Branch],'Branch Submission'!$A4,MainDB[Month], "January") -> 0 | C4: =COUNTIFS(MainDB[Branch],'Branch Submission'!$A4,MainDB[Month], "February") -> 2 | D4: =COUNTIFS(MainDB[Branch],'Branch Submission'!$A4,MainDB[Month], "March") -> 9 | E4: =COUNTIFS(MainDB[Branch],'Branch Submission'!$A4,MainDB[Month], "April") -> 0 | F4: =COUNTIFS(MainDB[Branch],'Branch Submission'!$A4,MainDB[Month], "May") -> 0 | G4: =COUNTIFS(MainDB[Branch],'Branch Submission'!$A4,MainDB[Month], "June") -> 4 | H4: =COUNTIFS(MainDB[Branch],'Branch Submission'!$A4,MainDB[Month], "July") -> 0 | I4: =COUNTIFS(MainDB[Branch],'Branch Submission'!$A4,MainDB[Month], "August") -> 0 | J4: =COUNTIFS(MainDB[Branch],'Branch Submission'!$A4,MainDB[Month], "September") -> 2 | K4: =COUNTIFS(MainDB[Branch],'Branch Submission'!$A4,MainDB[Month], "October") -> 0 | L4: =COUNTIFS(MainDB[Branch],'Branch Submission'!$A4,MainDB[Month], "November") -> 2 | M4: =COUNTIFS(MainDB[Branch],'Branch Submission'!$A4,MainDB[Month], "December") -> 0 | N4: =SUM(B4:M4) -> 19
A5: Esa-Oke, Osun State | B5: =COUNTIFS(MainDB[Branch],'Branch Submission'!$A5,MainDB[Month], "January") -> 2 | C5: =COUNTIFS(MainDB[Branch],'Branch Submission'!$A5,MainDB[Month], "February") -> 1 | D5: =COUNTIFS(MainDB[Branch],'Branch Submission'!$A5,MainDB[Month], "March") -> 0 | E5: =COUNTIFS(MainDB[Branch],'Branch Submission'!$A5,MainDB[Month], "April") -> 0 | F5: =COUNTIFS(MainDB[Branch],'Branch Submission'!$A5,MainDB[Month], "May") -> 0 | G5: =COUNTIFS(MainDB[Branch],'Branch Submission'!$A5,MainDB[Month], "June") -> 0 | H5: =COUNTIFS(MainDB[Branch],'Branch Submission'!$A5,MainDB[Month], "July") -> 0 | I5: =COUNTIFS(MainDB[Branch],'Branch Submission'!$A5,MainDB[Month], "August") -> 0 | J5: =COUNTIFS(MainDB[Branch],'Branch Submission'!$A5,MainDB[Month], "September") -> 0 | K5: =COUNTIFS(MainDB[Branch],'Branch Submission'!$A5,MainDB[Month], "October") -> 0 | L5: =COUNTIFS(MainDB[Branch],'Branch Submission'!$A5,MainDB[Month], "November") -> 0 | M5: =COUNTIFS(MainDB[Branch],'Branch Submission'!$A5,MainDB[Month], "December") -> 0 | N5: =SUM(B5:M5) -> 3
A6: Headquarters, Egbe-Idi, Ilesa, Osun State | B6: =COUNTIFS(MainDB[Branch],'Branch Submission'!$A6,MainDB[Month], "January") -> 0 | C6: =COUNTIFS(MainDB[Branch],'Branch Submission'!$A6,MainDB[Month], "February") -> 1 | D6: =COUNTIFS(MainDB[Branch],'Branch Submission'!$A6,MainDB[Month], "March") -> 5 | E6: =COUNTIFS(MainDB[Branch],'Branch Submission'!$A6,MainDB[Month], "April") -> 0 | F6: =COUNTIFS(MainDB[Branch],'Branch Submission'!$A6,MainDB[Month], "May") -> 0 | G6: =COUNTIFS(MainDB[Branch],'Branch Submission'!$A6,MainDB[Month], "June") -> 6 | H6: =COUNTIFS(MainDB[Branch],'Branch Submission'!$A6,MainDB[Month], "July") -> 0 | I6: =COUNTIFS(MainDB[Branch],'Branch Submission'!$A6,MainDB[Month], "August") -> 0 | J6: =COUNTIFS(MainDB[Branch],'Branch Submission'!$A6,MainDB[Month], "September") -> 4 | K6: =COUNTIFS(MainDB[Branch],'Branch Submission'!$A6,MainDB[Month], "October") -> 0 | L6: =COUNTIFS(MainDB[Branch],'Branch Submission'!$A6,MainDB[Month], "November") -> 3 | M6: =COUNTIFS(MainDB[Branch],'Branch Submission'!$A6,MainDB[Month], "December") -> 0 | N6: =SUM(B6:M6) -> 19

Sheet Monthly Submission
A1: Month | B1: No of Submission
A2: January | B2: =SUM(BranchDB[Jan]) -> 5
A3: February | B3: =SUM(BranchDB[Feb]) -> 7
A4: March | B4: =SUM(BranchDB[Mar]) -> 36
A5: April | B5: =SUM(BranchDB[Apr]) -> 3
A6: May | B6: =SUM(BranchDB[May]) -> 0
A7: June | B7: =SUM(BranchDB[Jun]) -> 22
A8: July | B8: =SUM(BranchDB[Jul]) -> 0
A9: August | B9: =SUM(BranchDB[Aug]) -> 0
A10: September | B10: =SUM(BranchDB[Sep]) -> 10
A11: October | B11: =SUM(BranchDB[Oct]) -> 1
A12: November | B12: =SUM(BranchDB[Nov]) -> 8
A13: December | B13: =SUM(BranchDB[Dec]) -> 0
A14: Total | B14: =SUM($B$2:$B$13) -> 92

Sheet Dashboard
